[2022-12-21 19:03:20,089] {taskinstance.py:1032} INFO - Dependencies all met for <TaskInstance: fireflow_dag.dbt_run_task manual__2022-12-21T18:55:06.292041+00:00 [queued]>
[2022-12-21 19:03:20,100] {taskinstance.py:1032} INFO - Dependencies all met for <TaskInstance: fireflow_dag.dbt_run_task manual__2022-12-21T18:55:06.292041+00:00 [queued]>
[2022-12-21 19:03:20,101] {taskinstance.py:1238} INFO - 
--------------------------------------------------------------------------------
[2022-12-21 19:03:20,101] {taskinstance.py:1239} INFO - Starting attempt 1 of 2
[2022-12-21 19:03:20,102] {taskinstance.py:1240} INFO - 
--------------------------------------------------------------------------------
[2022-12-21 19:03:20,111] {taskinstance.py:1259} INFO - Executing <Task(BashOperator): dbt_run_task> on 2022-12-21 18:55:06.292041+00:00
[2022-12-21 19:03:20,118] {standard_task_runner.py:52} INFO - Started process 1832 to run task
[2022-12-21 19:03:20,122] {standard_task_runner.py:76} INFO - Running: ['***', 'tasks', 'run', 'fireflow_dag', 'dbt_run_task', 'manual__2022-12-21T18:55:06.292041+00:00', '--job-id', '59', '--raw', '--subdir', 'DAGS_FOLDER/fireflow_batch_dag.py', '--cfg-path', '/tmp/tmpsbe13l70', '--error-file', '/tmp/tmp67x6ldhp']
[2022-12-21 19:03:20,124] {standard_task_runner.py:77} INFO - Job 59: Subtask dbt_run_task
[2022-12-21 19:03:20,171] {logging_mixin.py:109} INFO - Running <TaskInstance: fireflow_dag.dbt_run_task manual__2022-12-21T18:55:06.292041+00:00 [running]> on host ffb0f01832af
[2022-12-21 19:03:20,218] {taskinstance.py:1426} INFO - Exporting the following env vars:
AIRFLOW_CTX_DAG_OWNER=***
AIRFLOW_CTX_DAG_ID=fireflow_dag
AIRFLOW_CTX_TASK_ID=dbt_run_task
AIRFLOW_CTX_EXECUTION_DATE=2022-12-21T18:55:06.292041+00:00
AIRFLOW_CTX_DAG_RUN_ID=manual__2022-12-21T18:55:06.292041+00:00
[2022-12-21 19:03:20,220] {subprocess.py:62} INFO - Tmp dir root location: 
 /tmp
[2022-12-21 19:03:20,222] {subprocess.py:74} INFO - Running command: ['bash', '-c', 'docker compose run --workdir="//usr/app/***/dbt" dbt-bq-fireflow run --no-version-check']
[2022-12-21 19:03:20,235] {subprocess.py:85} INFO - Output:
[2022-12-21 19:03:20,246] {subprocess.py:89} INFO - bash: docker: command not found
[2022-12-21 19:03:20,247] {subprocess.py:93} INFO - Command exited with return code 127
[2022-12-21 19:03:20,260] {taskinstance.py:1700} ERROR - Task failed with exception
Traceback (most recent call last):
  File "/home/airflow/.local/lib/python3.7/site-packages/airflow/models/taskinstance.py", line 1329, in _run_raw_task
    self._execute_task_with_callbacks(context)
  File "/home/airflow/.local/lib/python3.7/site-packages/airflow/models/taskinstance.py", line 1455, in _execute_task_with_callbacks
    result = self._execute_task(context, self.task)
  File "/home/airflow/.local/lib/python3.7/site-packages/airflow/models/taskinstance.py", line 1511, in _execute_task
    result = execute_callable(context=context)
  File "/home/airflow/.local/lib/python3.7/site-packages/airflow/operators/bash.py", line 188, in execute
    f'Bash command failed. The command returned a non-zero exit code {result.exit_code}.'
airflow.exceptions.AirflowException: Bash command failed. The command returned a non-zero exit code 127.
[2022-12-21 19:03:20,270] {taskinstance.py:1277} INFO - Marking task as UP_FOR_RETRY. dag_id=fireflow_dag, task_id=dbt_run_task, execution_date=20221221T185506, start_date=20221221T190320, end_date=20221221T190320
[2022-12-21 19:03:20,286] {standard_task_runner.py:92} ERROR - Failed to execute job 59 for task dbt_run_task
Traceback (most recent call last):
  File "/home/airflow/.local/lib/python3.7/site-packages/airflow/task/task_runner/standard_task_runner.py", line 85, in _start_by_fork
    args.func(args, dag=self.dag)
  File "/home/airflow/.local/lib/python3.7/site-packages/airflow/cli/cli_parser.py", line 48, in command
    return func(*args, **kwargs)
  File "/home/airflow/.local/lib/python3.7/site-packages/airflow/utils/cli.py", line 92, in wrapper
    return f(*args, **kwargs)
  File "/home/airflow/.local/lib/python3.7/site-packages/airflow/cli/commands/task_command.py", line 298, in task_run
    _run_task_by_selected_method(args, dag, ti)
  File "/home/airflow/.local/lib/python3.7/site-packages/airflow/cli/commands/task_command.py", line 107, in _run_task_by_selected_method
    _run_raw_task(args, ti)
  File "/home/airflow/.local/lib/python3.7/site-packages/airflow/cli/commands/task_command.py", line 184, in _run_raw_task
    error_file=args.error_file,
  File "/home/airflow/.local/lib/python3.7/site-packages/airflow/utils/session.py", line 70, in wrapper
    return func(*args, session=session, **kwargs)
  File "/home/airflow/.local/lib/python3.7/site-packages/airflow/models/taskinstance.py", line 1329, in _run_raw_task
    self._execute_task_with_callbacks(context)
  File "/home/airflow/.local/lib/python3.7/site-packages/airflow/models/taskinstance.py", line 1455, in _execute_task_with_callbacks
    result = self._execute_task(context, self.task)
  File "/home/airflow/.local/lib/python3.7/site-packages/airflow/models/taskinstance.py", line 1511, in _execute_task
    result = execute_callable(context=context)
  File "/home/airflow/.local/lib/python3.7/site-packages/airflow/operators/bash.py", line 188, in execute
    f'Bash command failed. The command returned a non-zero exit code {result.exit_code}.'
airflow.exceptions.AirflowException: Bash command failed. The command returned a non-zero exit code 127.
[2022-12-21 19:03:20,334] {local_task_job.py:154} INFO - Task exited with return code 1
[2022-12-21 19:03:20,367] {local_task_job.py:264} INFO - 0 downstream tasks scheduled from follow-on schedule check
