[2022-12-21 14:51:39,832] {taskinstance.py:1032} INFO - Dependencies all met for <TaskInstance: fireflow_dag.load_to_gcs_task manual__2022-12-21T14:46:35.068087+00:00 [queued]>
[2022-12-21 14:51:39,840] {taskinstance.py:1032} INFO - Dependencies all met for <TaskInstance: fireflow_dag.load_to_gcs_task manual__2022-12-21T14:46:35.068087+00:00 [queued]>
[2022-12-21 14:51:39,841] {taskinstance.py:1238} INFO - 
--------------------------------------------------------------------------------
[2022-12-21 14:51:39,841] {taskinstance.py:1239} INFO - Starting attempt 2 of 2
[2022-12-21 14:51:39,842] {taskinstance.py:1240} INFO - 
--------------------------------------------------------------------------------
[2022-12-21 14:51:39,852] {taskinstance.py:1259} INFO - Executing <Task(PythonOperator): load_to_gcs_task> on 2022-12-21 14:46:35.068087+00:00
[2022-12-21 14:51:39,856] {standard_task_runner.py:52} INFO - Started process 1993 to run task
[2022-12-21 14:51:39,858] {standard_task_runner.py:76} INFO - Running: ['***', 'tasks', 'run', 'fireflow_dag', 'load_to_gcs_task', 'manual__2022-12-21T14:46:35.068087+00:00', '--job-id', '65', '--raw', '--subdir', 'DAGS_FOLDER/fireflow_batch_dag.py', '--cfg-path', '/tmp/tmp1rgyq977', '--error-file', '/tmp/tmptnq1o3ct']
[2022-12-21 14:51:39,860] {standard_task_runner.py:77} INFO - Job 65: Subtask load_to_gcs_task
[2022-12-21 14:51:39,903] {logging_mixin.py:109} INFO - Running <TaskInstance: fireflow_dag.load_to_gcs_task manual__2022-12-21T14:46:35.068087+00:00 [running]> on host 78bd7b303d21
[2022-12-21 14:51:39,944] {taskinstance.py:1426} INFO - Exporting the following env vars:
AIRFLOW_CTX_DAG_OWNER=***
AIRFLOW_CTX_DAG_ID=fireflow_dag
AIRFLOW_CTX_TASK_ID=load_to_gcs_task
AIRFLOW_CTX_EXECUTION_DATE=2022-12-21T14:46:35.068087+00:00
AIRFLOW_CTX_DAG_RUN_ID=manual__2022-12-21T14:46:35.068087+00:00
[2022-12-21 14:51:39,967] {taskinstance.py:1700} ERROR - Task failed with exception
Traceback (most recent call last):
  File "/home/airflow/.local/lib/python3.7/site-packages/airflow/models/taskinstance.py", line 1329, in _run_raw_task
    self._execute_task_with_callbacks(context)
  File "/home/airflow/.local/lib/python3.7/site-packages/airflow/models/taskinstance.py", line 1455, in _execute_task_with_callbacks
    result = self._execute_task(context, self.task)
  File "/home/airflow/.local/lib/python3.7/site-packages/airflow/models/taskinstance.py", line 1511, in _execute_task
    result = execute_callable(context=context)
  File "/home/airflow/.local/lib/python3.7/site-packages/airflow/operators/python.py", line 174, in execute
    return_value = self.execute_callable()
  File "/home/airflow/.local/lib/python3.7/site-packages/airflow/operators/python.py", line 185, in execute_callable
    return self.python_callable(*self.op_args, **self.op_kwargs)
  File "/opt/airflow/dags/fireflow_batch_dag.py", line 58, in load_data_to_gcs
    blob.upload_from_filename(f'{path_to_local_home}/{filename}')
  File "/home/airflow/.local/lib/python3.7/site-packages/google/cloud/storage/blob.py", line 2720, in upload_from_filename
    with open(filename, "rb") as file_obj:
FileNotFoundError: [Errno 2] No such file or directory: '/opt/airflow/customer.csv'
[2022-12-21 14:51:39,984] {taskinstance.py:1277} INFO - Marking task as FAILED. dag_id=fireflow_dag, task_id=load_to_gcs_task, execution_date=20221221T144635, start_date=20221221T145139, end_date=20221221T145139
[2022-12-21 14:51:39,994] {standard_task_runner.py:92} ERROR - Failed to execute job 65 for task load_to_gcs_task
Traceback (most recent call last):
  File "/home/airflow/.local/lib/python3.7/site-packages/airflow/task/task_runner/standard_task_runner.py", line 85, in _start_by_fork
    args.func(args, dag=self.dag)
  File "/home/airflow/.local/lib/python3.7/site-packages/airflow/cli/cli_parser.py", line 48, in command
    return func(*args, **kwargs)
  File "/home/airflow/.local/lib/python3.7/site-packages/airflow/utils/cli.py", line 92, in wrapper
    return f(*args, **kwargs)
  File "/home/airflow/.local/lib/python3.7/site-packages/airflow/cli/commands/task_command.py", line 298, in task_run
    _run_task_by_selected_method(args, dag, ti)
  File "/home/airflow/.local/lib/python3.7/site-packages/airflow/cli/commands/task_command.py", line 107, in _run_task_by_selected_method
    _run_raw_task(args, ti)
  File "/home/airflow/.local/lib/python3.7/site-packages/airflow/cli/commands/task_command.py", line 184, in _run_raw_task
    error_file=args.error_file,
  File "/home/airflow/.local/lib/python3.7/site-packages/airflow/utils/session.py", line 70, in wrapper
    return func(*args, session=session, **kwargs)
  File "/home/airflow/.local/lib/python3.7/site-packages/airflow/models/taskinstance.py", line 1329, in _run_raw_task
    self._execute_task_with_callbacks(context)
  File "/home/airflow/.local/lib/python3.7/site-packages/airflow/models/taskinstance.py", line 1455, in _execute_task_with_callbacks
    result = self._execute_task(context, self.task)
  File "/home/airflow/.local/lib/python3.7/site-packages/airflow/models/taskinstance.py", line 1511, in _execute_task
    result = execute_callable(context=context)
  File "/home/airflow/.local/lib/python3.7/site-packages/airflow/operators/python.py", line 174, in execute
    return_value = self.execute_callable()
  File "/home/airflow/.local/lib/python3.7/site-packages/airflow/operators/python.py", line 185, in execute_callable
    return self.python_callable(*self.op_args, **self.op_kwargs)
  File "/opt/airflow/dags/fireflow_batch_dag.py", line 58, in load_data_to_gcs
    blob.upload_from_filename(f'{path_to_local_home}/{filename}')
  File "/home/airflow/.local/lib/python3.7/site-packages/google/cloud/storage/blob.py", line 2720, in upload_from_filename
    with open(filename, "rb") as file_obj:
FileNotFoundError: [Errno 2] No such file or directory: '/opt/airflow/customer.csv'
[2022-12-21 14:51:40,032] {local_task_job.py:154} INFO - Task exited with return code 1
[2022-12-21 14:51:40,064] {local_task_job.py:264} INFO - 0 downstream tasks scheduled from follow-on schedule check
